(base) C:\windows\system32>cd \

(base) C:\>cd test

(base) C:\test>django-admin startproject RestaurantShare

(base) C:\test>cd Restaurant
지정된 경로를 찾을 수 없습니다.

(base) C:\test>cd RestaurantShare

(base) C:\test\RestaurantShare>python manage.py startapp shareRes

(base) C:\test\RestaurantShare>python manage.py startapp sendEmail

(base) C:\test\RestaurantShare>python manage.py migrate
Operations to perform:
  Apply all migrations: admin, auth, contenttypes, sessions
Running migrations:
  Applying contenttypes.0001_initial... OK
  Applying auth.0001_initial... OK
  Applying admin.0001_initial... OK
  Applying admin.0002_logentry_remove_auto_add... OK
  Applying admin.0003_logentry_add_action_flag_choices... OK
  Applying contenttypes.0002_remove_content_type_name... OK
  Applying auth.0002_alter_permission_name_max_length... OK
  Applying auth.0003_alter_user_email_max_length... OK
  Applying auth.0004_alter_user_username_opts... OK
  Applying auth.0005_alter_user_last_login_null... OK
  Applying auth.0006_require_contenttypes_0002... OK
  Applying auth.0007_alter_validators_add_error_messages... OK
  Applying auth.0008_alter_user_username_max_length... OK
  Applying auth.0009_alter_user_last_name_max_length... OK
  Applying auth.0010_alter_group_name_max_length... OK
  Applying auth.0011_update_proxy_permissions... OK
  Applying auth.0012_alter_user_first_name_max_length... OK
  Applying sessions.0001_initial... OK

(base) C:\test\RestaurantShare>python manage.py createsuperuser
Username (leave blank to use 'kbs'): dkdfl784
Email address: wleks784
Error: Enter a valid email address.
Email address: asdklfj@naver.com
Password:
Password (again):
Superuser created successfully.

(base) C:\test\RestaurantShare>cd \

(base) C:\>cd test

(base) C:\test>tree /F RestaurantShare
Windows 볼륨에 대한 폴더 경로의 목록입니다.
볼륨 일련 번호는 466B-C8B5입니다.
C:\TEST\RESTAURANTSHARE
│  db.sqlite3
│  manage.py
│
├─RestaurantShare
│  │  asgi.py
│  │  settings.py
│  │  urls.py
│  │  wsgi.py
│  │  __init__.py
│  │
│  └─__pycache__
│          settings.cpython-38.pyc
│          urls.cpython-38.pyc
│          wsgi.cpython-38.pyc
│          __init__.cpython-38.pyc
│
├─sendEmail
│  │  admin.py
│  │  apps.py
│  │  models.py
│  │  tests.py
│  │  views.py
│  │  __init__.py
│  │
│  ├─migrations
│  │  │  __init__.py
│  │  │
│  │  └─__pycache__
│  │          __init__.cpython-38.pyc
│  │
│  └─__pycache__
│          admin.cpython-38.pyc
│          apps.cpython-38.pyc
│          models.cpython-38.pyc
│          __init__.cpython-38.pyc
│
└─shareRes
    │  admin.py
    │  apps.py
    │  models.py
    │  tests.py
    │  views.py
    │  __init__.py
    │
    ├─migrations
    │  │  __init__.py
    │  │
    │  └─__pycache__
    │          __init__.cpython-38.pyc
    │
    └─__pycache__
            admin.cpython-38.pyc
            apps.cpython-38.pyc
            models.cpython-38.pyc
            __init__.cpython-38.pyc


(base) C:\test>cd RestaurantShare

(base) C:\test\RestaurantShare>python manage.py makemigrations
Traceback (most recent call last):
  File "manage.py", line 22, in <module>
    main()
  File "manage.py", line 18, in main
    execute_from_command_line(sys.argv)
  File "C:\ProgramData\Anaconda3\lib\site-packages\django\core\management\__init__.py", line 419, in execute_from_command_line
    utility.execute()
  File "C:\ProgramData\Anaconda3\lib\site-packages\django\core\management\__init__.py", line 395, in execute
    django.setup()
  File "C:\ProgramData\Anaconda3\lib\site-packages\django\__init__.py", line 24, in setup
    apps.populate(settings.INSTALLED_APPS)
  File "C:\ProgramData\Anaconda3\lib\site-packages\django\apps\registry.py", line 114, in populate
    app_config.import_models()
  File "C:\ProgramData\Anaconda3\lib\site-packages\django\apps\config.py", line 301, in import_models
    self.models_module = import_module(models_module_name)
  File "C:\ProgramData\Anaconda3\lib\importlib\__init__.py", line 127, in import_module
    return _bootstrap._gcd_import(name[level:], package, level)
  File "<frozen importlib._bootstrap>", line 1014, in _gcd_import
  File "<frozen importlib._bootstrap>", line 991, in _find_and_load
  File "<frozen importlib._bootstrap>", line 975, in _find_and_load_unlocked
  File "<frozen importlib._bootstrap>", line 671, in _load_unlocked
  File "<frozen importlib._bootstrap_external>", line 783, in exec_module
  File "<frozen importlib._bootstrap>", line 219, in _call_with_frames_removed
  File "C:\test\RestaurantShare\shareRes\models.py", line 4, in <module>
    class Category(models.Model):
  File "C:\test\RestaurantShare\shareRes\models.py", line 5, in Category
    category_name = Models.CharField(max_length=100)
NameError: name 'Models' is not defined

(base) C:\test\RestaurantShare>python manage.py makemigrations
Traceback (most recent call last):
  File "manage.py", line 22, in <module>
    main()
  File "manage.py", line 18, in main
    execute_from_command_line(sys.argv)
  File "C:\ProgramData\Anaconda3\lib\site-packages\django\core\management\__init__.py", line 419, in execute_from_command_line
    utility.execute()
  File "C:\ProgramData\Anaconda3\lib\site-packages\django\core\management\__init__.py", line 395, in execute
    django.setup()
  File "C:\ProgramData\Anaconda3\lib\site-packages\django\__init__.py", line 24, in setup
    apps.populate(settings.INSTALLED_APPS)
  File "C:\ProgramData\Anaconda3\lib\site-packages\django\apps\registry.py", line 114, in populate
    app_config.import_models()
  File "C:\ProgramData\Anaconda3\lib\site-packages\django\apps\config.py", line 301, in import_models
    self.models_module = import_module(models_module_name)
  File "C:\ProgramData\Anaconda3\lib\importlib\__init__.py", line 127, in import_module
    return _bootstrap._gcd_import(name[level:], package, level)
  File "<frozen importlib._bootstrap>", line 1014, in _gcd_import
  File "<frozen importlib._bootstrap>", line 991, in _find_and_load
  File "<frozen importlib._bootstrap>", line 975, in _find_and_load_unlocked
  File "<frozen importlib._bootstrap>", line 671, in _load_unlocked
  File "<frozen importlib._bootstrap_external>", line 783, in exec_module
  File "<frozen importlib._bootstrap>", line 219, in _call_with_frames_removed
  File "C:\test\RestaurantShare\shareRes\models.py", line 7, in <module>
    class Restaurant(Models.Model):
NameError: name 'Models' is not defined

(base) C:\test\RestaurantShare>python manage.py makemigrations
Traceback (most recent call last):
  File "manage.py", line 22, in <module>
    main()
  File "manage.py", line 18, in main
    execute_from_command_line(sys.argv)
  File "C:\ProgramData\Anaconda3\lib\site-packages\django\core\management\__init__.py", line 419, in execute_from_command_line
    utility.execute()
  File "C:\ProgramData\Anaconda3\lib\site-packages\django\core\management\__init__.py", line 395, in execute
    django.setup()
  File "C:\ProgramData\Anaconda3\lib\site-packages\django\__init__.py", line 24, in setup
    apps.populate(settings.INSTALLED_APPS)
  File "C:\ProgramData\Anaconda3\lib\site-packages\django\apps\registry.py", line 122, in populate
    app_config.ready()
  File "C:\ProgramData\Anaconda3\lib\site-packages\django\contrib\admin\apps.py", line 27, in ready
    self.module.autodiscover()
  File "C:\ProgramData\Anaconda3\lib\site-packages\django\contrib\admin\__init__.py", line 24, in autodiscover
    autodiscover_modules('admin', register_to=site)
  File "C:\ProgramData\Anaconda3\lib\site-packages\django\utils\module_loading.py", line 47, in autodiscover_modules
    import_module('%s.%s' % (app_config.name, module_to_search))
  File "C:\ProgramData\Anaconda3\lib\importlib\__init__.py", line 127, in import_module
    return _bootstrap._gcd_import(name[level:], package, level)
  File "<frozen importlib._bootstrap>", line 1014, in _gcd_import
  File "<frozen importlib._bootstrap>", line 991, in _find_and_load
  File "<frozen importlib._bootstrap>", line 975, in _find_and_load_unlocked
  File "<frozen importlib._bootstrap>", line 671, in _load_unlocked
  File "<frozen importlib._bootstrap_external>", line 783, in exec_module
  File "<frozen importlib._bootstrap>", line 219, in _call_with_frames_removed
  File "C:\test\RestaurantShare\shareRes\admin.py", line 4, in <module>
    from ShareRes.models import Category, Restaurant
ModuleNotFoundError: No module named 'ShareRes'

(base) C:\test\RestaurantShare>python manage.py makemigrations
Migrations for 'shareRes':
  shareRes\migrations\0001_initial.py
    - Create model Category
    - Create model Restaurant

(base) C:\test\RestaurantShare>python manage.py migrate
Operations to perform:
  Apply all migrations: admin, auth, contenttypes, sessions, shareRes
Running migrations:
  Applying shareRes.0001_initial... OK

(base) C:\test\RestaurantShare>python manage.py runserver
Watching for file changes with StatReloader
Performing system checks...

System check identified no issues (0 silenced).
August 27, 2021 - 16:55:40
Django version 3.2.6, using settings 'RestaurantShare.settings'
Starting development server at http://127.0.0.1:8000/
Quit the server with CTRL-BREAK.

(base) C:\test\RestaurantShare>

(base) C:\test\RestaurantShare>python manage.py migrate
Operations to perform:
  Apply all migrations: admin, auth, contenttypes, sessions, shareRes
Running migrations:
  No migrations to apply.

(base) C:\test\RestaurantShare>python manage\.py runserver
python: can't open file 'manage\.py': [Errno 2] No such file or directory

(base) C:\test\RestaurantShare>python manage.py runserver
Watching for file changes with StatReloader
Performing system checks...

System check identified no issues (0 silenced).
August 27, 2021 - 16:56:54
Django version 3.2.6, using settings 'RestaurantShare.settings'
Starting development server at http://127.0.0.1:8000/
Quit the server with CTRL-BREAK.
[27/Aug/2021 16:57:29] "GET / HTTP/1.1" 200 10697
[27/Aug/2021 16:57:47] "GET / HTTP/1.1" 200 10697

(base) C:\test\RestaurantShare>python manage.py runserver
Watching for file changes with StatReloader
Performing system checks...

System check identified no issues (0 silenced).
August 27, 2021 - 16:58:01
Django version 3.2.6, using settings 'RestaurantShare.settings'
Starting development server at http://127.0.0.1:8000/
Quit the server with CTRL-BREAK.
C:\test\RestaurantShare\RestaurantShare\urls.py changed, reloading.
Watching for file changes with StatReloader
Performing system checks...

Exception in thread django-main-thread:
Traceback (most recent call last):
  File "C:\ProgramData\Anaconda3\lib\threading.py", line 932, in _bootstrap_inner
    self.run()
  File "C:\ProgramData\Anaconda3\lib\threading.py", line 870, in run
    self._target(*self._args, **self._kwargs)
  File "C:\ProgramData\Anaconda3\lib\site-packages\django\utils\autoreload.py", line 64, in wrapper
    fn(*args, **kwargs)
  File "C:\ProgramData\Anaconda3\lib\site-packages\django\core\management\commands\runserver.py", line 118, in inner_run
    self.check(display_num_errors=True)
  File "C:\ProgramData\Anaconda3\lib\site-packages\django\core\management\base.py", line 419, in check
    all_issues = checks.run_checks(
  File "C:\ProgramData\Anaconda3\lib\site-packages\django\core\checks\registry.py", line 76, in run_checks
    new_errors = check(app_configs=app_configs, databases=databases)
  File "C:\ProgramData\Anaconda3\lib\site-packages\django\core\checks\urls.py", line 13, in check_url_config
    return check_resolver(resolver)
  File "C:\ProgramData\Anaconda3\lib\site-packages\django\core\checks\urls.py", line 23, in check_resolver
    return check_method()
  File "C:\ProgramData\Anaconda3\lib\site-packages\django\urls\resolvers.py", line 412, in check
    for pattern in self.url_patterns:
  File "C:\ProgramData\Anaconda3\lib\site-packages\django\utils\functional.py", line 48, in __get__
    res = instance.__dict__[self.name] = self.func(instance)
  File "C:\ProgramData\Anaconda3\lib\site-packages\django\urls\resolvers.py", line 598, in url_patterns
    patterns = getattr(self.urlconf_module, "urlpatterns", self.urlconf_module)
  File "C:\ProgramData\Anaconda3\lib\site-packages\django\utils\functional.py", line 48, in __get__
    res = instance.__dict__[self.name] = self.func(instance)
  File "C:\ProgramData\Anaconda3\lib\site-packages\django\urls\resolvers.py", line 591, in urlconf_module
    return import_module(self.urlconf_name)
  File "C:\ProgramData\Anaconda3\lib\importlib\__init__.py", line 127, in import_module
    return _bootstrap._gcd_import(name[level:], package, level)
  File "<frozen importlib._bootstrap>", line 1014, in _gcd_import
  File "<frozen importlib._bootstrap>", line 991, in _find_and_load
  File "<frozen importlib._bootstrap>", line 975, in _find_and_load_unlocked
  File "<frozen importlib._bootstrap>", line 671, in _load_unlocked
  File "<frozen importlib._bootstrap_external>", line 783, in exec_module
  File "<frozen importlib._bootstrap>", line 219, in _call_with_frames_removed
  File "C:\test\RestaurantShare\RestaurantShare\urls.py", line 22, in <module>
    path('sendEmail/', include('sendEmail.urls')),
  File "C:\ProgramData\Anaconda3\lib\site-packages\django\urls\conf.py", line 34, in include
    urlconf_module = import_module(urlconf_module)
  File "C:\ProgramData\Anaconda3\lib\importlib\__init__.py", line 127, in import_module
    return _bootstrap._gcd_import(name[level:], package, level)
  File "<frozen importlib._bootstrap>", line 1014, in _gcd_import
  File "<frozen importlib._bootstrap>", line 991, in _find_and_load
  File "<frozen importlib._bootstrap>", line 973, in _find_and_load_unlocked
ModuleNotFoundError: No module named 'sendEmail.urls'
Traceback (most recent call last):
  File "manage.py", line 22, in <module>
    main()
  File "manage.py", line 18, in main
    execute_from_command_line(sys.argv)
  File "C:\ProgramData\Anaconda3\lib\site-packages\django\core\management\__init__.py", line 419, in execute_from_command_line
    utility.execute()
  File "C:\ProgramData\Anaconda3\lib\site-packages\django\core\management\__init__.py", line 413, in execute
    self.fetch_command(subcommand).run_from_argv(self.argv)
  File "C:\ProgramData\Anaconda3\lib\site-packages\django\core\management\base.py", line 354, in run_from_argv
    self.execute(*args, **cmd_options)
  File "C:\ProgramData\Anaconda3\lib\site-packages\django\core\management\commands\runserver.py", line 61, in execute
    super().execute(*args, **options)
  File "C:\ProgramData\Anaconda3\lib\site-packages\django\core\management\base.py", line 398, in execute
    output = self.handle(*args, **options)
  File "C:\ProgramData\Anaconda3\lib\site-packages\django\core\management\commands\runserver.py", line 96, in handle
    self.run(**options)
  File "C:\ProgramData\Anaconda3\lib\site-packages\django\core\management\commands\runserver.py", line 103, in run
    autoreload.run_with_reloader(self.inner_run, **options)
  File "C:\ProgramData\Anaconda3\lib\site-packages\django\utils\autoreload.py", line 638, in run_with_reloader
    start_django(reloader, main_func, *args, **kwargs)
  File "C:\ProgramData\Anaconda3\lib\site-packages\django\utils\autoreload.py", line 623, in start_django
    reloader.run(django_main_thread)
  File "C:\ProgramData\Anaconda3\lib\site-packages\django\utils\autoreload.py", line 329, in run
    self.run_loop()
  File "C:\ProgramData\Anaconda3\lib\site-packages\django\utils\autoreload.py", line 335, in run_loop
    next(ticker)
  File "C:\ProgramData\Anaconda3\lib\site-packages\django\utils\autoreload.py", line 375, in tick
    for filepath, mtime in self.snapshot_files():
  File "C:\ProgramData\Anaconda3\lib\site-packages\django\utils\autoreload.py", line 391, in snapshot_files
    for file in self.watched_files():
  File "C:\ProgramData\Anaconda3\lib\site-packages\django\utils\autoreload.py", line 289, in watched_files
    yield from iter_all_python_module_files()
  File "C:\ProgramData\Anaconda3\lib\site-packages\django\utils\autoreload.py", line 116, in iter_all_python_module_files
    return iter_modules_and_files(modules, frozenset(_error_files))
  File "C:\ProgramData\Anaconda3\lib\site-packages\django\utils\autoreload.py", line 152, in iter_modules_and_files
    if not path.exists():
  File "C:\ProgramData\Anaconda3\lib\pathlib.py", line 1400, in exists
    self.stat()
  File "C:\ProgramData\Anaconda3\lib\pathlib.py", line 1197, in stat
    return self._accessor.stat(self)
OSError: [WinError 123] 파일 이름, 디렉터리 이름 또는 볼륨 레이블 구문이 잘못되었습니다: '<frozen importlib._bootstrap>'

(base) C:\test\RestaurantShare>python manage.py runserver
Watching for file changes with StatReloader
Performing system checks...

Exception in thread django-main-thread:
Traceback (most recent call last):
  File "C:\ProgramData\Anaconda3\lib\threading.py", line 932, in _bootstrap_inner
    self.run()
  File "C:\ProgramData\Anaconda3\lib\threading.py", line 870, in run
    self._target(*self._args, **self._kwargs)
  File "C:\ProgramData\Anaconda3\lib\site-packages\django\utils\autoreload.py", line 64, in wrapper
    fn(*args, **kwargs)
  File "C:\ProgramData\Anaconda3\lib\site-packages\django\core\management\commands\runserver.py", line 118, in inner_run
    self.check(display_num_errors=True)
  File "C:\ProgramData\Anaconda3\lib\site-packages\django\core\management\base.py", line 419, in check
    all_issues = checks.run_checks(
  File "C:\ProgramData\Anaconda3\lib\site-packages\django\core\checks\registry.py", line 76, in run_checks
    new_errors = check(app_configs=app_configs, databases=databases)
  File "C:\ProgramData\Anaconda3\lib\site-packages\django\core\checks\urls.py", line 13, in check_url_config
    return check_resolver(resolver)
  File "C:\ProgramData\Anaconda3\lib\site-packages\django\core\checks\urls.py", line 23, in check_resolver
    return check_method()
  File "C:\ProgramData\Anaconda3\lib\site-packages\django\urls\resolvers.py", line 412, in check
    for pattern in self.url_patterns:
  File "C:\ProgramData\Anaconda3\lib\site-packages\django\utils\functional.py", line 48, in __get__
    res = instance.__dict__[self.name] = self.func(instance)
  File "C:\ProgramData\Anaconda3\lib\site-packages\django\urls\resolvers.py", line 598, in url_patterns
    patterns = getattr(self.urlconf_module, "urlpatterns", self.urlconf_module)
  File "C:\ProgramData\Anaconda3\lib\site-packages\django\utils\functional.py", line 48, in __get__
    res = instance.__dict__[self.name] = self.func(instance)
  File "C:\ProgramData\Anaconda3\lib\site-packages\django\urls\resolvers.py", line 591, in urlconf_module
    return import_module(self.urlconf_name)
  File "C:\ProgramData\Anaconda3\lib\importlib\__init__.py", line 127, in import_module
    return _bootstrap._gcd_import(name[level:], package, level)
  File "<frozen importlib._bootstrap>", line 1014, in _gcd_import
  File "<frozen importlib._bootstrap>", line 991, in _find_and_load
  File "<frozen importlib._bootstrap>", line 975, in _find_and_load_unlocked
  File "<frozen importlib._bootstrap>", line 671, in _load_unlocked
  File "<frozen importlib._bootstrap_external>", line 783, in exec_module
  File "<frozen importlib._bootstrap>", line 219, in _call_with_frames_removed
  File "C:\test\RestaurantShare\RestaurantShare\urls.py", line 22, in <module>
    path('sendEmail/', include('sendEmail.urls')),
  File "C:\ProgramData\Anaconda3\lib\site-packages\django\urls\conf.py", line 34, in include
    urlconf_module = import_module(urlconf_module)
  File "C:\ProgramData\Anaconda3\lib\importlib\__init__.py", line 127, in import_module
    return _bootstrap._gcd_import(name[level:], package, level)
  File "<frozen importlib._bootstrap>", line 1014, in _gcd_import
  File "<frozen importlib._bootstrap>", line 991, in _find_and_load
  File "<frozen importlib._bootstrap>", line 973, in _find_and_load_unlocked
ModuleNotFoundError: No module named 'sendEmail.urls'
Traceback (most recent call last):
  File "manage.py", line 22, in <module>
    main()
  File "manage.py", line 18, in main
    execute_from_command_line(sys.argv)
  File "C:\ProgramData\Anaconda3\lib\site-packages\django\core\management\__init__.py", line 419, in execute_from_command_line
    utility.execute()
  File "C:\ProgramData\Anaconda3\lib\site-packages\django\core\management\__init__.py", line 413, in execute
    self.fetch_command(subcommand).run_from_argv(self.argv)
  File "C:\ProgramData\Anaconda3\lib\site-packages\django\core\management\base.py", line 354, in run_from_argv
    self.execute(*args, **cmd_options)
  File "C:\ProgramData\Anaconda3\lib\site-packages\django\core\management\commands\runserver.py", line 61, in execute
    super().execute(*args, **options)
  File "C:\ProgramData\Anaconda3\lib\site-packages\django\core\management\base.py", line 398, in execute
    output = self.handle(*args, **options)
  File "C:\ProgramData\Anaconda3\lib\site-packages\django\core\management\commands\runserver.py", line 96, in handle
    self.run(**options)
  File "C:\ProgramData\Anaconda3\lib\site-packages\django\core\management\commands\runserver.py", line 103, in run
    autoreload.run_with_reloader(self.inner_run, **options)
  File "C:\ProgramData\Anaconda3\lib\site-packages\django\utils\autoreload.py", line 638, in run_with_reloader
    start_django(reloader, main_func, *args, **kwargs)
  File "C:\ProgramData\Anaconda3\lib\site-packages\django\utils\autoreload.py", line 623, in start_django
    reloader.run(django_main_thread)
  File "C:\ProgramData\Anaconda3\lib\site-packages\django\utils\autoreload.py", line 329, in run
    self.run_loop()
  File "C:\ProgramData\Anaconda3\lib\site-packages\django\utils\autoreload.py", line 335, in run_loop
    next(ticker)
  File "C:\ProgramData\Anaconda3\lib\site-packages\django\utils\autoreload.py", line 375, in tick
    for filepath, mtime in self.snapshot_files():
  File "C:\ProgramData\Anaconda3\lib\site-packages\django\utils\autoreload.py", line 391, in snapshot_files
    for file in self.watched_files():
  File "C:\ProgramData\Anaconda3\lib\site-packages\django\utils\autoreload.py", line 289, in watched_files
    yield from iter_all_python_module_files()
  File "C:\ProgramData\Anaconda3\lib\site-packages\django\utils\autoreload.py", line 116, in iter_all_python_module_files
    return iter_modules_and_files(modules, frozenset(_error_files))
  File "C:\ProgramData\Anaconda3\lib\site-packages\django\utils\autoreload.py", line 152, in iter_modules_and_files
    if not path.exists():
  File "C:\ProgramData\Anaconda3\lib\pathlib.py", line 1400, in exists
    self.stat()
  File "C:\ProgramData\Anaconda3\lib\pathlib.py", line 1197, in stat
    return self._accessor.stat(self)
OSError: [WinError 123] 파일 이름, 디렉터리 이름 또는 볼륨 레이블 구문이 잘못되었습니다: '<frozen importlib._bootstrap>'

(base) C:\test\RestaurantShare>python manage.py migrate
Traceback (most recent call last):
  File "manage.py", line 22, in <module>
    main()
  File "manage.py", line 18, in main
    execute_from_command_line(sys.argv)
  File "C:\ProgramData\Anaconda3\lib\site-packages\django\core\management\__init__.py", line 419, in execute_from_command_line
    utility.execute()
  File "C:\ProgramData\Anaconda3\lib\site-packages\django\core\management\__init__.py", line 413, in execute
    self.fetch_command(subcommand).run_from_argv(self.argv)
  File "C:\ProgramData\Anaconda3\lib\site-packages\django\core\management\base.py", line 354, in run_from_argv
    self.execute(*args, **cmd_options)
  File "C:\ProgramData\Anaconda3\lib\site-packages\django\core\management\base.py", line 398, in execute
    output = self.handle(*args, **options)
  File "C:\ProgramData\Anaconda3\lib\site-packages\django\core\management\base.py", line 89, in wrapped
    res = handle_func(*args, **kwargs)
  File "C:\ProgramData\Anaconda3\lib\site-packages\django\core\management\commands\migrate.py", line 75, in handle
    self.check(databases=[database])
  File "C:\ProgramData\Anaconda3\lib\site-packages\django\core\management\base.py", line 419, in check
    all_issues = checks.run_checks(
  File "C:\ProgramData\Anaconda3\lib\site-packages\django\core\checks\registry.py", line 76, in run_checks
    new_errors = check(app_configs=app_configs, databases=databases)
  File "C:\ProgramData\Anaconda3\lib\site-packages\django\core\checks\urls.py", line 13, in check_url_config
    return check_resolver(resolver)
  File "C:\ProgramData\Anaconda3\lib\site-packages\django\core\checks\urls.py", line 23, in check_resolver
    return check_method()
  File "C:\ProgramData\Anaconda3\lib\site-packages\django\urls\resolvers.py", line 412, in check
    for pattern in self.url_patterns:
  File "C:\ProgramData\Anaconda3\lib\site-packages\django\utils\functional.py", line 48, in __get__
    res = instance.__dict__[self.name] = self.func(instance)
  File "C:\ProgramData\Anaconda3\lib\site-packages\django\urls\resolvers.py", line 598, in url_patterns
    patterns = getattr(self.urlconf_module, "urlpatterns", self.urlconf_module)
  File "C:\ProgramData\Anaconda3\lib\site-packages\django\utils\functional.py", line 48, in __get__
    res = instance.__dict__[self.name] = self.func(instance)
  File "C:\ProgramData\Anaconda3\lib\site-packages\django\urls\resolvers.py", line 591, in urlconf_module
    return import_module(self.urlconf_name)
  File "C:\ProgramData\Anaconda3\lib\importlib\__init__.py", line 127, in import_module
    return _bootstrap._gcd_import(name[level:], package, level)
  File "<frozen importlib._bootstrap>", line 1014, in _gcd_import
  File "<frozen importlib._bootstrap>", line 991, in _find_and_load
  File "<frozen importlib._bootstrap>", line 975, in _find_and_load_unlocked
  File "<frozen importlib._bootstrap>", line 671, in _load_unlocked
  File "<frozen importlib._bootstrap_external>", line 783, in exec_module
  File "<frozen importlib._bootstrap>", line 219, in _call_with_frames_removed
  File "C:\test\RestaurantShare\RestaurantShare\urls.py", line 22, in <module>
    path('sendEmail/', include('sendEmail.urls')),
  File "C:\ProgramData\Anaconda3\lib\site-packages\django\urls\conf.py", line 34, in include
    urlconf_module = import_module(urlconf_module)
  File "C:\ProgramData\Anaconda3\lib\importlib\__init__.py", line 127, in import_module
    return _bootstrap._gcd_import(name[level:], package, level)
  File "<frozen importlib._bootstrap>", line 1014, in _gcd_import
  File "<frozen importlib._bootstrap>", line 991, in _find_and_load
  File "<frozen importlib._bootstrap>", line 973, in _find_and_load_unlocked
ModuleNotFoundError: No module named 'sendEmail.urls'

(base) C:\test\RestaurantShare>python manage.py runserver
Watching for file changes with StatReloader
Performing system checks...

System check identified no issues (0 silenced).
August 27, 2021 - 17:03:27
Django version 3.2.6, using settings 'RestaurantShare.settings'
Starting development server at http://127.0.0.1:8000/
Quit the server with CTRL-BREAK.
[27/Aug/2021 17:03:36] "GET / HTTP/1.1" 200 8353
[27/Aug/2021 17:03:43] "GET /categoryCreate/ HTTP/1.1" 200 3269
[27/Aug/2021 17:03:56] "POST /categoryCreate/create HTTP/1.1" 302 0
[27/Aug/2021 17:03:56] "GET / HTTP/1.1" 200 8577
[27/Aug/2021 17:03:58] "GET /categoryCreate/ HTTP/1.1" 200 4002
[27/Aug/2021 17:04:02] "POST /categoryCreate/create HTTP/1.1" 302 0
[27/Aug/2021 17:04:02] "GET / HTTP/1.1" 200 8801
[27/Aug/2021 17:04:03] "GET /categoryCreate/ HTTP/1.1" 200 4735
[27/Aug/2021 17:04:06] "POST /categoryCreate/create HTTP/1.1" 302 0
[27/Aug/2021 17:04:06] "GET / HTTP/1.1" 200 9025
[27/Aug/2021 17:04:18] "GET /restaurantCreate/ HTTP/1.1" 200 5444
[27/Aug/2021 17:04:35] "POST /restaurantCreate/create HTTP/1.1" 302 0
[27/Aug/2021 17:04:35] "GET / HTTP/1.1" 200 9869
[27/Aug/2021 17:04:39] "GET /restaurantDetail/1 HTTP/1.1" 200 4996
[27/Aug/2021 17:04:53] "GET /restaurantDetail/1 HTTP/1.1" 200 4996
[27/Aug/2021 17:04:59] "GET / HTTP/1.1" 200 9869
[27/Aug/2021 17:05:01] "GET /restaurantDetail/1 HTTP/1.1" 200 4996
[27/Aug/2021 17:05:03] "GET / HTTP/1.1" 200 9869
[27/Aug/2021 17:05:13] "POST /sendEmail/send/ HTTP/1.1" 200 9